Workbook

Sheet R&P
A2: IMAIGAL TRUST
A4: NO.41, MEKKELATHOTTAM, ALAM PALAYAM, SIRUKALANJI, UTHUKULI, ERODE,TAMILNADU - 638751
A6: RECEIPTS & PAYMENT FOR THE YEAR ENDING 31ST MARCH 2023
A8: RECEIPTS | C8: AMOUNT | E8: PAYMENTS | G8: AMOUNT
A10: To | B10: OPENING BALANCE | E10: By | F10: WELFARE EXPENSES
B11: Cash in Hand | C11: 7604 | E11: " | F11: Sfurti- Implementing Agency for Cluster & Swatch Bharath Awareness and Activities | G11: 530589
A12: s | B12: Cash at Bank | E12: " | F12: Soft Intervention Activities covered: | G12: 278430
A13: " | B13: Canara Bank - 1311 | C13: 25705886 | E13: " | F13: SFURTI Cluster -Hard Intervention Activities | G13: 8184557
A14: " | B14: Canara Bank - 1312 | C14: 602346 | E14: " | F14: Watershed Development Fund Programme - CBP Phase- Mulanur, Tirupur | G14: =712878+44288 -> 757166
A15: " | B15: Canara Bank - 1336 | C15: 1566640 | E15: " | F15: Training on Integrated Farming System , Namakkal | G15: 40000
A16: " | B16: Canana Bank - 5779 | C16: 986 | E16: " | F16: NTI of Agri Clinic & Agri Business Training Centre Scheme of MANAGE ,MoAgriculture, GOI | G16: =813750+810850 -> 1624600
A17: " | B17: Canara Bank - 5778 | C17: 4996 | E17: " | F17: Awareness of Cluster for Handicrafts Artisans Karur | G17: 25000
A18: " | B18: Canara Bank - 9440 | C18: 82257 | E18: " | F18: Farmer Producer Organisation - Awareness | G18: 40000
A19: " | B19: Union Bank of India- 2634 | C19: 324590.73 | D19: =SUM(C11:C19) -> 28295306 | E19: " | F19: Training on Organic Farming | G19: 50000
E20: " | F20: Environment Health & Safety Awareness Programme | G20: 40000
B21: INCOMES | E21: " | F21: EDP in Agri & Allied Business Opportunities for Rural Youths | G21: 28750
A22: " | B22: Donation | D22: 2529014 | F22: Watershed Development Fund Programme - FIP Phase- Vellakoil, Tirupur | G22: 10000
A23: " | B23: Trustee Contribution | D23: 253000 | E23: " | F23: Watershed Development Fund Programmes - Management Activities | G23: 180000
A24: " | B24: Grant - Coir Board | D24: - | F24: Watershed Development Fund Programme -Pre CBP - Kodaiyur I, Karur | G24: 60000
E25: " | F25: Watershed Development Fund Programme -Pre CBP - Kodaiyur II, Karur | G25: 60000
A26: " | B26: Grant - NABARD | D26: 11749196 | E26: " | F26: FPO Formation and Supporting activities as POPI Aravakurichi, Karur | G26: 292000
A27: ' | B27: Grant - NABCONS | D27: =L111 -> 368334 | E27: " | F27: FPO Formation and Supporting activities as POPI Vellakoil, Tirupur | G27: 292000
E28: " | F28: Training programme for Herbal & Medicinal Plants plantation and its Value Addition | G28: 160000
B29: Grant - MANAGE, Min of Agriculture, GOI | D29: 1947850 | E29: " | F29: Awareness programme in Credit Linkage Supports to farmers and Youths | G29: 42000
E30: " | F30: Awareness for Women SHG /JLG Formation and business start ups | G30: 80000
F31: Afforestation and Global Farming Programe | G31: 135000
H34: (Contd..2)
E36: ::2 ::
A37: RECEIPTS | C37: AMOUNT | E37: PAYMENTS | G37: AMOUNT
E39: " | F39: Livelihood and Enterprise Development Programme (LEDP) - Coconut Shell Value Added Products, Tirupur | G39: 70000
E40: " | F40: Livelihood and Enterprise Development Programme (LEDP) - Coconut and Erode Turmeric Value Added Products, Erode | G40: 497500
E41: " | F41: Livelihood and Enterprise Development Programme (LEDP) - Home Based Cloth Value Added products- Karur | G41: 497500
E42: " | F42: Palmyra collection, Plantation | G42: 80000
E43: " | F43: pepper, coffee value added products at kollihills Cluster formation field programmes | G43: 40000
E44: " | F44: FPO Formation and Development- RSA ,Karur and Tirupur | G44: 600000
F45: Cluster Development support in Coconut value added products , Erode | G45: 75000
E46: " | F46: Awareness programme of ACABC Scheme | G46: 100000
E47: " | F47: FPO Development Activities - Resource Agency- Erode and Tirupur | G47: 409260
E48: " | F48: Training on value addition for Tribal Peoples | G48: 75000
E49: " | F49: Transgender Development- MEDP on food value added products, tirupur | G49: 90000
...

Sheet I&E
A1: ='R&P'!A2:G2 -> IMAIGAL TRUST
A3: ='R&P'!A4:G4 -> NO.41, MEKKELATHOTTAM, ALAM PALAYAM, SIRUKALANJI, UTHUKULI, ERODE,TAMILNADU - 638751
A5: INCOME AND EXPENDITURE ACCOUNT FOR THE YEAR ENDED 31st MARCH, 2023
B7: EXPENDITURE | C7: AMOUNT | F7: INCOME | G7: AMOUNT
A9: To | B9: ='R&P'!F10 -> WELFARE EXPENSES | E9: By | F9: ='R&P'!B21 -> INCOMES | H9: ='R&P'!D21 -> 0
A10: " | B10: ='R&P'!F11 -> Sfurti- Implementing Agency for Cluster & Swatch Bharath Awareness and Activities | C10: ='R&P'!G11 -> 530589 | E10: " | F10: ='R&P'!B22 -> Donation | H10: ='R&P'!D22 -> 2529014
A11: " | B11: ='R&P'!F12 -> Soft Intervention Activities covered: | C11: ='R&P'!G12 -> 278430 | E11: " | F11: ='R&P'!B23 -> Trustee Contribution | H11: ='R&P'!D23 -> 253000
A12: " | B12: ='R&P'!F14 -> Watershed Development Fund Programme - CBP Phase- Mulanur, Tirupur | C12: ='R&P'!G14 -> 757166 | E12: " | F12: ='R&P'!B24 -> Grant - Coir Board | H12: ='R&P'!D24 -> -
A13: " | B13: ='R&P'!F15 -> Training on Integrated Farming System , Namakkal | C13: ='R&P'!G15 -> 40000 | E13: " | F13: ='R&P'!B26 -> Grant - NABARD | H13: ='R&P'!D26+368334 -> 12117530
A14: " | B14: ='R&P'!F16 -> NTI of Agri Clinic & Agri Business Training Centre Scheme of MANAGE ,MoAgriculture, GOI | C14: ='R&P'!G16 -> 1624600 | E14: " | F14: ='R&P'!B29 -> Grant - MANAGE, Min of Agriculture, GOI | H14: ='R&P'!D29 -> 1947850
A15: " | B15: ='R&P'!F17 -> Awareness of Cluster for Handicrafts Artisans Karur | C15: ='R&P'!G17 -> 25000 | E15: " | F15: TDS Receivable | H15: 40926
A16: " | B16: ='R&P'!F18 -> Farmer Producer Organisation - Awareness | C16: ='R&P'!G18 -> 40000
A17: " | B17: ='R&P'!F19 -> Training on Organic Farming | C17: ='R&P'!G19 -> 50000
A18: " | B18: ='R&P'!F20 -> Environment Health & Safety Awareness Programme | C18: ='R&P'!G20 -> 40000
A19: " | B19: ='R&P'!F21 -> EDP in Agri & Allied Business Opportunities for Rural Youths | C19: ='R&P'!G21 -> 28750
A20: " | B20: ='R&P'!F22 -> Watershed Development Fund Programme - FIP Phase- Vellakoil, Tirupur | C20: ='R&P'!G22 -> 10000
B21: ='R&P'!F23 -> Watershed Development Fund Programmes - Management Activities | C21: ='R&P'!G23 -> 180000
A22: " | B22: ='R&P'!F24 -> Watershed Development Fund Programme -Pre CBP - Kodaiyur I, Karur | C22: ='R&P'!G24 -> 60000
B23: ='R&P'!F25 -> Watershed Development Fund Programme -Pre CBP - Kodaiyur II, Karur | C23: ='R&P'!G25 -> 60000
A24: " | B24: ='R&P'!F26 -> FPO Formation and Supporting activities as POPI Aravakurichi, Karur | C24: ='R&P'!G26 -> 292000
A25: " | B25: ='R&P'!F27 -> FPO Formation and Supporting activities as POPI Vellakoil, Tirupur | C25: ='R&P'!G27 -> 292000
A26: " | B26: ='R&P'!F28 -> Training programme for Herbal & Medicinal Plants plantation and its Value Addition | C26: ='R&P'!G28 -> 160000
A27: " | B27: ='R&P'!F29 -> Awareness programme in Credit Linkage Supports to farmers and Youths | C27: ='R&P'!G29 -> 42000
A28: " | B28: ='R&P'!F30 -> Awareness for Women SHG /JLG Formation and business start ups | C28: ='R&P'!G30 -> 80000
A29: " | B29: ='R&P'!F31 -> Afforestation and Global Farming Programe | C29: ='R&P'!G31 -> 135000
H31: (Contd..2)
D33: ::2::
B35: EXPENDITURE | C35: AMOUNT | F35: INCOME | G35: AMOUNT
A37: " | B37: ='R&P'!F39 -> Livelihood and Enterprise Development Programme (LEDP) - Coconut Shell Value Added Products, Tirupur | C37: ='R&P'!G39 -> 70000
A38: " | B38: ='R&P'!F40 -> Livelihood and Enterprise Development Programme (LEDP) - Coconut and Erode Turmeric Value Added Products, Erode | C38: ='R&P'!G40 -> 497500
A39: " | B39: ='R&P'!F41 -> Livelihood and Enterprise Development Programme (LEDP) - Home Based Cloth Value Added products- Karur | C39: ='R&P'!G41 -> 497500
A40: " | B40: ='R&P'!F42 -> Palmyra collection, Plantation | C40: ='R&P'!G42 -> 80000
A41: " | B41: ='R&P'!F43 -> pepper, coffee value added products at kollihills Cluster formation field programmes | C41: ='R&P'!G43 -> 40000
A42: " | B42: ='R&P'!F44 -> FPO Formation and Development- RSA ,Karur and Tirupur | C42: ='R&P'!G44 -> 600000
B43: ='R&P'!F45 -> Cluster Development support in Coconut value added products , Erode | C43: ='R&P'!G45 -> 75000
A44: " | B44: ='R&P'!F46 -> Awareness programme of ACABC Scheme | C44: ='R&P'!G46 -> 100000
A45: " | B45: ='R&P'!F47 -> FPO Development Activities - Resource Agency- Erode and Tirupur | C45: ='R&P'!G47 -> 409260
A46: " | B46: ='R&P'!F48 -> Training on value addition for Tribal Peoples | C46: ='R&P'!G48 -> 75000
A47: " | B47: ='R&P'!F49 -> Transgender Development- MEDP on food value added products, tirupur | C47: ='R&P'!G49 -> 90000
B48: ='R&P'!F50 -> Transgender Development- Marketing Supports | C48: ='R&P'!G50 -> 60000
...

Sheet B Sheet
A1: ='R&P'!A2:G2 -> IMAIGAL TRUST
A3: ='R&P'!A4:G4 -> NO.41, MEKKELATHOTTAM, ALAM PALAYAM, SIRUKALANJI, UTHUKULI, ERODE,TAMILNADU - 638751
A5: BALANCE SHEET AS ON 31st MARCH, 2023
A7: LIABILITIES | B7: AMOUNT | D7: ASSETS | E7: AMOUNT
A9: TRUST FUND | D9: FIXED ASSETS
A10: As per last Balance Sheet | B10: 8420225.6 | D10: As Per Schedule | F10: ='Fixed Assets'!H51 -> 4448779.1
A11: Add :: Excess of Income
A12: Over Expenditure | B12: ='I&E'!D77 -> 5132093.2 | C12: =B10+B12 -> 13552319 | D12: CURRENT ASSETS
D13: Office Deposits - 1 Nos | E13: 600000
D14: Hostel Deposits | E14: 250000
D15: Extension Deposit - 2 Nos | E15: 120000 | F15: =SUM(E13:E15) -> 970000
D17: Income Receivable
D18: Add :: During the Year | E18: 368334 | F18: =E18 -> 368334
D20: TDS Receivable | E20: 129191
D21: Add :: During the Year | E21: ='I&E'!H15 -> 40926 | F21: =SUM(E20:E21) -> 170117
D23: CLOSING BALANCE
D24: ='R&P'!F90 -> Cash in Hand | E24: ='R&P'!G90 -> 8005 | I24: =B10 -> 8420225.6
D25: ='R&P'!F91 -> Cash at Bank | E25: ='R&P'!G91 -> 0 | H25: Add | I25: ='I&E'!H79 -> 16888320
D26: ='R&P'!F92 -> Canara Bank -1311 | E26: ='R&P'!G92 -> 17520077 | H26: Less | I26: ='I&E'!D79 -> 16888320
D27: ='R&P'!F93 -> Canara Bank - 1312 | E27: ='R&P'!G93 -> 71094 | H27: Net Worth | I27: =I24+I25-I26 -> 8420225.6 | J27: Net Worth
D28: ='R&P'!F95 -> Canara Bank - 5778 | E28: ='R&P'!G95 -> 1670480
D29: ='R&P'!F96 -> Canana Bank - 5779 | E29: ='R&P'!G96 -> 527456
D30: ='R&P'!F98 -> Union Bank of India- 2634 | E30: ='R&P'!G98 -> 415179.05 | F30: =SUM(E24:E30) -> 20212291 | I30: =+I25-I26 -> 0
A32: TOTAL | C32: =SUM(C8:C31) -> 13552319 | D32: TOTAL | F32: =SUM(F8:F31) -> 26169521
A34: ='R&P'!A104 -> Place: Erode | F34: Subject to our report in
A35: ='R&P'!A105 -> Date: 13.08.2022 | F35: Form No. 10B of even date
C37: =C32-F32 -> -12617202

Sheet Fixed Assets
A1: ='R&P'!A2:G2 -> IMAIGAL TRUST
A3: SCHEDULE OF FIXED ASSETS
A5: Sl.No. | B5: Fixed Assets | C5: W.D.V. As on 01.04.2021 | D5: Additions during the year | E5: Total | F5: Rate | G5: Depreciation | H5: W.D.V. As on 31.03.2022
B7: Land & Building
A8: 1 | B8: Infrastructure - Partition, Furniture | C8: 1583703 | D8: =187500+50000+50000 -> 287500 | E8: =C8+D8 -> 1871203 | F8: 0.05 | G8: =E8*F8 -> 93560.15 | H8: =E8-G8 -> 1777642.9
B10: Furniture & Fittings
A11: 1 | B11: Electrical | C11: 116640 | D11: 0 | E11: =C11+D11 -> 116640 | F11: 0.1 | G11: =E11*F11 -> 11664 | H11: =E11-G11 -> 104976
A12: 2 | B12: Furniture | C12: 145800 | D12: 0 | E12: =C12+D12 -> 145800 | F12: 0.1 | G12: =E12*F12 -> 14580 | H12: =E12-G12 -> 131220
A13: 3 | B13: Hostel Beds | C13: 135810 | D13: 37500 | E13: =C13+D13 -> 173310 | F13: 0.1 | G13: =E13*F13 -> 17331 | H13: =E13-G13 -> 155979
A14: 4 | B14: Aluminium Partician Extension | C14: 36450 | D14: 0 | E14: =C14+D14 -> 36450 | F14: 0.1 | G14: =E14*F14 -> 3645 | H14: =E14-G14 -> 32805
A15: 5 | B15: Banner, Pantry Things, Dustbins | C15: 23328 | D15: 0 | E15: =C15+D15 -> 23328 | F15: 0.1 | G15: =E15*F15 -> 2332.8 | H15: =E15-G15 -> 20995.2
A16: 6 | B16: Boards, LCD Screens | C16: 20412 | D16: 0 | E16: =C16+D16 -> 20412 | F16: 0.1 | G16: =E16*F16 -> 2041.2 | H16: =E16-G16 -> 18370.8
A17: 7 | B17: Computer Table Setup | C17: 105705 | D17: 0 | E17: =C17+D17 -> 105705 | F17: 0.1 | G17: =E17*F17 -> 10570.5 | H17: =E17-G17 -> 95134.5
A18: 8 | B18: Chairs - 200 Nos | C18: 87480 | D18: 0 | E18: =C18+D18 -> 87480 | F18: 0.1 | G18: =E18*F18 -> 8748 | H18: =E18-G18 -> 78732
A19: 9 | B19: Dinning Table for 50 Members | C19: 72900 | D19: 0 | E19: =C19+D19 -> 72900 | F19: 0.1 | G19: =E19*F19 -> 7290 | H19: =E19-G19 -> 65610
A20: 10 | B20: Flips Chairs | C20: 51030 | D20: 0 | E20: =C20+D20 -> 51030 | F20: 0.1 | G20: =E20*F20 -> 5103 | H20: =E20-G20 -> 45927
A21: 11 | B21: Fans & Lights | C21: 129762 | D21: 0 | E21: =C21+D21 -> 129762 | F21: 0.1 | G21: =E21*F21 -> 12976.2 | H21: =E21-G21 -> 116785.8
A22: 12 | B22: Fans - Ceiling | C22: 109350 | D22: 0 | E22: =C22+D22 -> 109350 | F22: 0.1 | G22: =E22*F22 -> 10935 | H22: =E22-G22 -> 98415
... A30: 20 | B30: Training Support Machine | C30: 44100 | D30: 13000 | E30: =C30+D30 -> 57100 | F30: 0.1 | G30: =E30*F30 -> 5710 | H30: =E30-G30 -> 51390
H32: (Contd…2)
D34: ::2::
A36: Sl.No. | B36: Fixed Assets | C36: W.D.V. As on 01.04.2021 | D36: Additions during the year | E36: Total | F36: Rate | G36: Depreciation | H36: W.D.V. As on 31.03.2022
B38: Electrical Equipments
B39: Agri Lab Materials | C39: 134682.5 | D39: 144000 | E39: =C39+D39 -> 278682.5 | F39: 0.15 | G39: =E39*F39 -> 41802.375 | H39: =E39-G39 -> 236880.12
B40: Air Conditioner | C40: 113135 | D40: 17500 | E40: =C40+D40 -> 130635 | F40: 0.15 | G40: =E40*F40 -> 19595.25 | H40: =E40-G40 -> 111039.75
A41: 3 | B41: Camera - 18 Nos | C41: 49130 | D41: 0 | E41: =C41+D41 -> 49130 | F41: 0.15 | G41: =E41*F41 -> 7369.5 | H41: =E41-G41 -> 41760.5
A42: 4 | B42: Electrical Wiring & UPS Battery | C42: 430333.75 | D42: 80000 | E42: =C42+D42 -> 510333.75 | F42: 0.15 | G42: =E42*F42 -> 76550.062 | H42: =E42-G42 -> 433783.69
A43: 5 | B43: Micro Irrigation, Organic Grower Materials | C43: 63869 | D43: 0 | E43: =C43+D43 -> 63869 | F43: 0.15 | G43: =E43*F43 -> 9580.35 | H43: =E43-G43 -> 54288.65
A44: 6 | B44: Printer Scanner | C44: 24565 | D44: 0 | E44: =C44+D44 -> 24565 | F44: 0.15 | G44: =E44*F44 -> 3684.75 | H44: =E44-G44 -> 20880.25
A45: 7 | B45: Projectors - 4 Nos | C45: 61412.5 | D45: 0 | E45: =C45+D45 -> 61412.5 | F45: 0.15 | G45: =E45*F45 -> 9211.875 | H45: =E45-G45 -> 52200.625
B47: Computer
A48: 1 | B48: Computer | C48: 174840 | D48: 67000 | E48: =C48+D48 -> 241840 | F48: 0.4 | G48: =E48*F48 -> 96736 | H48: =E48-G48 -> 145104
A49: 2 | B49: Printer & Scanner | C49: 20520 | D49: 15000 | E49: =C49+D49 -> 35520 | F49: 0.4 | G49: =E49*F49 -> 14208 | H49: =E49-G49 -> 21312
B51: 2021-2022 | C51: =SUM(C6:C50) -> 4332231.5 | D51: =SUM(D8:D50) -> 661500 | E51: =SUM(E8:E50) -> 4993731.5 | G51: =SUM(G6:G50) -> 544952.39 | H51: =SUM(H8:H50) -> 4448779.1

Sheet DONATIONS FINAL 
B2: IMAIGAL TRUST , DONATIONS DETAILS - FY-2022-23
B3: Sl. No. | C3: ID Code | D3: Unique Identification Number | E3: Name of donor | F3: Address of donor | G3: Donation Type | H3: Mode of receipt | I3: Amount of donation (Indian rupees) | J3: REC NO | K3: PAN NO
B4: 1 | C4: Aadhaar Number | D4: 561808253547 | E4: CHETHAN CHANDRASEKAR | F4: COIMBATORE | G4: Corpus | H4: Electronic modes including account payee cheque/draft | I4: 300000 | J4: 1401202301 | K4: AQCPC8094J
B5: 2 | C5: Aadhaar Number | D5: 967503356310 | E5: SUSHANTH NANDAN | F5: MAHADEVAPURAM, COIMBATORE | G5: Corpus | H5: Electronic modes including account payee cheque/draft | I5: 200000 | J5: 20012301 | K5: FEJPS7637H
B6: 3 | C6: Aadhaar Number | D6: 310264611888 | E6: GEETHARANI.P | F6: NAMAKKAL | G6: Corpus | H6: Electronic modes including account payee cheque/draft | I6: 300000 | J6: 13022023 | K6: ALQPG4842D
B7: 4 | C7: Aadhaar Number | D7: 309585840982 | E7: RAJKUMAR | F7: NAMAKKAL | G7: Corpus | H7: Electronic modes including account payee cheque/draft | I7: 140000 | J7: 16022023 | K7: BNSPR3432F
B8: 5 | C8: Aadhaar Number | D8: 528518095736 | E8: S.SENTHILKUMAR | F8: NAMAKKAL | G8: Corpus | H8: Electronic modes including account payee cheque/draft | I8: 140000 | J8: 18022023 | K8: DOVPS6104B
B9: 6 | C9: Aadhaar Number | D9: 3187 7755 6398 | E9: POOVENTHAN | F9: NAMAKKAL | G9: Corpus | H9: Electronic modes including account payee cheque/draft | I9: 300000 | K9: ATOPP0306P
B10: 7 | C10: Aadhaar Number | D10: 540845538857 | E10: R.M. SUBRAMANIAN | F10: ERODE | G10: Corpus | H10: Electronic modes including account payee cheque/draft | I10: 300000 | J10: 3103202301 | K10: APGPS3343K
E11: NANDHIVARMAN | F11: ERODE | G11: Corpus | H11: Electronic modes including account payee cheque/draft | I11: 12000 | K11: ZVA1637198
I12: =SUM(I4:I11) -> 1692000
B13: 8 | C13: Elector's photo identity number | D13: TN/15/095/0111486 | E13: K.RAMASAMY | F13: NAMAKKAL | G13: Corpus | H13: Cash | I13: 150000
B14: 9 | C14: Permanent Account Number | D14: CJTPP1215N | E14: Ponnusamy | F14: ERODE | G14: Corpus | H14: Others | I14: 200000 | K14: CJTPP1215N
B15: 10 | C15: Aadhaar Number | D15: 583864389699 | E15: PRAVEEN | F15: NAMAKKAL | G15: Corpus | H15: Cash | I15: 100000
B16: 11 | C16: Permanent Account Number | D16: BNAPS6055D | E16: SURESH T | F16: NAMAKKAL | G16: Corpus | H16: Others | I16: 150000
B17: 12 | C17: Aadhaar Number | D17: 579598332491 | E17: GOKUL | F17: TIRUPUR | G17: Corpus | H17: Kind | I17: 100000
B18: 13 | C18: Permanent Account Number | D18: CVM3049426 | E18: RAMYA V | F18: NAMAKKAL | G18: Corpus | H18: Others | I18: 100000
B19: 14 | C19: Aadhaar Number | D19: 385086045065 | E19: LENIN VEERA PANDIYAN | F19: ERODE | G19: Corpus | H19: Others | I19: 100000
B20: 15 | C20: Aadhaar Number | D20: 8494 9966 6929 | E20: Gajendraprabu | F20: NAMAKKAL | G20: Corpus | H20: Cash | I20: 100000
B21: 16 | C21: Aadhaar Number | D21: 695655589056 | E21: SATYA | F21: NAMAKKAL | G21: Corpus | H21: Others | I21: 50000
B22: 17 | C22: Aadhaar Number | D22: 740802279695 | E22: NANJUDESHWARAN | F22: NAMAKKAL | G22: Corpus | H22: Others | I22: 100000
B23: 18 | C23: Aadhaar Number | D23: 545940073478 | E23: HARISHANKAR | F23: ERODE | G23: Corpus | H23: Kind | I23: 50000
I24: =SUM(I13:I23) -> 1200000
E27: TOTAL FUND RECEIVED IN BANK | F27: 5811176
E28: OPENING BALANCE | F28: 324590
E29: FUND NABARD- | F29: =90000+70000+55000+90000+10000+117500+497500 -> 930000
E30: MANAGE,Min of Agri ,HYDERABAD | F30: =488250+648750+488250+322600 -> 1947850
E31: coirboard | F31: =5000+78570+43465+100780+7275+37240+49500+81915 -> 403745
E32: NABCONS | F32: 368334
E33: OTHERS | F33: =129840+1000+1000+3000+3000+12000 -> 149840
E34: DONATIONS | F34: =I12 -> 1692000
F35: =SUM(F28:F34) -> 5816359
E36: CORPUS DONATIONS | F36: =I24+I12 -> 2892000

Sheet programmes
G1: s
A2: IMAIGAL TRUST
A3: ANNUAL ACTIVITY REPORT : 2022-2023
A4: S.NO | B4: PROGRAMMES | C4: Department/ Financial Support | D4: PROJECT COST (RS)
A5: 1 | B5: Sfurti- Implementing Agency for Cluster & Swatch Bharath Awareness and Activities | C5: Coir Board, MoMSME, GOI | D5: 531252
A6: 2 | B6: Soft Intervention Activities covered: | C6: Coir Board, MoMSME, GOI | D6: 279044
A7: 3 | B7: Watershed Development Fund Programme - CBP Phase- Mulanur, Tirupur | C7: NABARD | D7: =712878+44288 -> 757166
A8: 4 | B8: Training on Integrated Farming System , Namakkal | C8: Imaigal Trust | D8: 40000
A9: 5 | B9: NTI of Agri Clinic & Agri Business Training Centre Scheme of MANAGE ,MoAgriculture, GOI | C9: MANAGE,Ministry of Agriculture, GOI | D9: =813750+810850 -> 1624600
A10: 6 | B10: Awareness of Cluster for Handicrafts Artisans Karur | C10: Imaigal Trust | D10: 25000
A11: 7 | B11: Farmer Producer Organisation - Awareness | C11: Imaigal Trust | D11: 40000
A12: 8 | B12: Training on Organic Farming | C12: Imaigal Trust | D12: 50000
A13: 9 | B13: Environment Health & Safety Awareness Programme | C13: Imaigal Trust | D13: 40000
A14: 10 | B14: EDP in Agri & Allied Business Opportunities for Rural Youths | C14: Imaigal Trust | D14: 28750
A15: 11 | B15: Watershed Development Fund Programme - FIP Phase- Vellakoil, Tirupur | C15: NABARD | D15: 10000
A16: 12 | B16: Watershed Development Fund Programmes - Management Activities | C16: NABARD | D16: 180000
A17: 13 | B17: Watershed Development Fund Programme -Pre CBP - Kodaiyur I, Karur | C17: NABARD | D17: 60000
A18: 14 | B18: Watershed Development Fund Programme -Pre CBP - Kodaiyur II, Karur | C18: NABARD | D18: 60000
A19: 15 | B19: FPO Formation and Supporting activities as POPI Aravakurichi, Karur | C19: NABARD | D19: 292000
A20: 16 | B20: FPO Formation and Supporting activities as POPI Vellakoil, Tirupur | C20: NABARD | D20: 292000
A21: 17 | B21: Training programme for Herbal & Medicinal Plants plantation and its Value Addition | C21: Imaigal Trust | D21: 160000
... A53: 49 | B53: Agriculture Extension Services Centre | C53: Imaigal Trust | D53: 396500
C54: TOTAL | D54: =SUM(D5:D53) -> 11210572

Sheet BANK ACCOUNTS 
A1: UNION BANK OF INDIA , ERODE- COMMON ACCOUNT
A2: S.No | B2: ACCOUNT NAME AND ADDRESS | C2: IFSC CODE | D2: ACCOUNT NUMBER | E2: BANK NAME | F2: CHEQUE BOOK FROM TO | G2: CURRENT PRESENCE OF PASS BOOK
A3: 1 | B3: IMAIGAL TRUST | C3: UBIN0537918 | D3: 278411100002634 | E3: UNION BANK OF INDIA
A4: FOR WATERSHED PROJECT - BANK ACCOUNT NUMBER DETAILS
A5: S.No | B5: ACCOUNT NAME AND ADDRESS | C5: IFSC CODE | D5: ACCOUNT NUMBER | E5: BANK NAME | F5: CHEQUE BOOK FROM TO | G5: CURRENT PRESENCE OF PASS BOOK
A6: 2 | B6: MAYILRANGAM SENAPATHIPALAYAM WATERSHED MANAGEMENT FUND 41 MEKALATHOTTAM ALAMPALAYAM SIRUKALANJI UTHUKULI ERODE - 638 751 | C6: CNRB0001027 | D6: 1027101035779 | E6: CANARA | F6: 338626 to 338650 | G6: YES
A7: SELLAPPAMATTI BANK ACCOUNT NUMBER DETAIL (RURAL HAAT - 2)
A8: S.No | B8: ACCOUNT NAME AND ADDRESS | C8: IFSC CODE | D8: ACCOUNT NUMBER | E8: BANK NAME | F8: CHEQUE BOOK - 2 FROM TO | G8: CURRENT PRESENCE OF PASS BOOK
A9: 3 | B9: IMAIGAL TRUST - RURAL HAAT MANAGEMENT FUND 41 MEKALATHOTTAM ALAMPALAYAM SIRUKALANJI UTHUKULI ERODE - 638 751 | C9: CNRB0001666 | D9: 110024229440 | E9: CANARA | F9: 497256 to 497275 607693 to 607705 | G9: NO
A10: SELLAPPAMATTI BANK ACCOUNT NUMBER DETAIL (FPO - IMAIGAL TRUST POPI)
A11: S.No | B11: ACCOUNT NAME AND ADDRESS | C11: IFSC CODE | D11: ACCOUNT NUMBER | E11: BANK NAME | F11: CHEQUE BOOK -2 FROM TO | G11: CURRENT PRESENCE OF PASS BOOK
A12: 4 | B12: IMAIGAL TRUST POPI MANAGEMENT FUND 41 MEKALATHOTTAM ALAMPALAYAM SIRUKALANJI UTHUKULI ERODE - 638 751 | C12: CNRB0001666 | D12: 1666101015891 | E12: CANARA | F12: 197747 to 197760 400142 to 400160 | G12: NO
A13: FOR IA - ERODE KONGU COIR CLUSTER PROJECT
A14: S.No | B14: ACCOUNT NAME AND ADDRESS | C14: IFSC CODE | D14: ACCOUNT NUMBER | E14: BANK NAME | F14: CHEQUE BOOK FROM TO | G14: CURRENT PRESENCE OF PASS BOOK
A15: 5 | B15: SI ACCOUNT ERODE KONGU COIR CLUSTER SF NO 461 ICHIPALAYAM VILLAGE KODUMUDI TALUK KODUMUDI ERODE 638 151 TN INDIA PINMZIP - 638 151 | C15: CNRB0001240 | D15: 1240201001336 | E15: CANARA | F15: NO | G15: YES
A16: 6 | B16: HI ACCOUNT ERODE KONGU COIR CLUSTER SF NO 461 ICHIPALAYAM VILLAGE KODUMUDI TALUK KODUMUDI ERODE 638 151 TN INDIA PINMZIP - 638 151 | C16: CNRB0001240 | D16: 1240201001311 | E16: CANARA | F16: NO | G16: YES
A17: 7 | B17: IA ACCOUNT ERODE KONGU COIR CLUSTER SF NO 461 ICHIPALAYAM VILLAGE KODUMUDI TALUK KODUMUDI ERODE 638 151 TN INDIA PINMZIP - 638 151 | C17: CNRB0001240 | D17: 1240201001312 | E17: CANARA | F17: NO | G17: YES
